# BaselineAnalyzer

C#初心者に優しいアナライザーパッケージ

[![BaselineAnalyzer](Images/BaselineAnalyzer.100.png)](https://github.com/kekyo/BaselineAnalyzer)

----

[English language is here](https://github.com/kekyo/BaselineAnalyzer/blob/main/docs/BLA0002.md)

## BLA0002: Avoid using 'throw ex;' in catch blocks, use 'throw;' instead to preserve stack trace

これは、例外を再スローする際に、 `throw` 句を使わずに `throw ex` のように、元の例外オブジェクトを指定した場合に発生します:

```csharp
public void Foo()
{
    try
    {
        // なにかする...
    }
    catch (Exception ex)
    {
        Console.WriteLine("Caught an exception!");

        // 元の例外オブジェクトを指定してスローする...
        throw ex;
    }
}
```

一見すると問題ないように見えますが、このようにスローすると、例外発生元を示すスタックトレース情報が失われ、例外は「ここ」で発生したかのように扱われます。
その結果、例外をログに記録した場合に、ログ内に正しくないスタックトレースが格納されたり、デバッガで例外の正しい発生個所を追跡できなくなったりします。

例外発生時に、何か特別な処理を行いたいだけである場合は、例外を「再スロー」させます。再スローは、特別な構文 `throw` 句で実現します:

```csharp
public void Foo()
{
    try
    {
        // なにかする...
    }
    catch (Exception ex)
    {
        Console.WriteLine("Caught an exception!");

        // 元の例外オブジェクトを「再スロー」する
        throw;
    }
}
```
