# BaselineAnalyzer

C#初心者に優しいアナライザーパッケージ

[![BaselineAnalyzer](Images/BaselineAnalyzer.100.png)](https://github.com/kekyo/BaselineAnalyzer)

----

[English language is here](https://github.com/kekyo/BaselineAnalyzer/blob/main/docs/BLA0001.md)

## BLA0001: The catch block does not contain a throw statement

これは、例外を `catch` した際に、例外をスローすることなく `catch` ブロックを抜けるようなコードを記述すると発生します:

```csharp
public void Foo()
{
    try
    {
        // なにかする...
    }
    catch (Exception ex)
    {
        Console.WriteLine("Caught an exception!");

        // 例外をスローしない...
    }
}
```

このようなコードは、例外が含む危険な状況を無視する可能性があります。
問題を修正する例を示します:

```csharp
public void Foo()
{
    try
    {
        // なにかする...
    }
    catch (Exception ex)
    {
        Console.WriteLine("Caught an exception!");
        
        // 例外を再スローする
        throw;
    }
}
```

上記のように、 `catch` ブロック内で例外がスローされれば問題はありません。
或いは、別の例外にラップしてスローする事が考えられます:

```csharp
public void Foo()
{
    try
    {
        // なにかする...
    }
    catch (Exception ex)
    {
        Console.WriteLine("Caught an exception!");
        
        // 例外をラップしてスローする
        throw new FormatException("Invalid form", ex);
    }
}
```

#### なぜですか？

例外には、例外的な事象、つまり正常には発生しない異常な状況が発生した事を伝える役割があります。
`catch` ブロックでスローしないと言う事は、異常な状態を「無視」したことに繋がる可能性があり、もっと大きな問題に気が付けない可能性があります。
そのような状況を早期に発見するためにも、例外を握りつぶさない方が良いのです。
